Workbook

Sheet Detail1
A1: Details for Count of Round - Position: QB, Round: 1
A3: Year | B3: Position | C3: Rookie? | D3: RK | E3: Player | F3: Team | G3: ADP | H3: GP | I3: 1 | J3: 2 | K3: 3 | L3: 4 | M3: 5 | N3: 6 | O3: 7 | P3: 8 | Q3: 9 | R3: 10 | S3: 11 | T3: 12 | U3: 13 | V3: 14 | W3: 15 | X3: 16 | Y3: 17 | Z3: 18 | AA3: AVG | AB3: Total Points | AC3: TTL | AD3: Round | AE3: Boom 10 | AF3: Boom 15 | AG3: Boom 20 | AH3: Boom 25 | AI3: Boom 30 | AJ3: Boom 10% | AK3: Boom 15% | AL3: Boom 20% | AM3: Boom 25% | AN3: Boom 30%
A4: 2024 | B4: QB | C4: No | D4: 1 | E4: Lamar Jackson | F4: BAL | G4: 43 | H4: 17 | I4: 25.1 | J4: 17.4 | K4: 26 | L4: 23.6 | M4: 33.4 | N4: 19.9 | O4: 34.4 | P4: 24.2 | Q4: 23.6 | R4: 32.9 | S4: 15.9 | T4: 22.6 | U4: 25.4 | V4: BYE | W4: 36.1 | X4: 21.5 | Y4: 29.4 | Z4: 23 | AA4: 25.6 | AB4: 411.4 | AC4: 434.4 | AD4: 1 | AE4: 16 | AF4: 17 | AG4: 14 | AH4: 8 | AI4: 4 | AJ4: 1 | AK4: 1 | AL4: 0.82352941 | AM4: 0.47058824 | AN4: 0.23529412
A5: 2025 | B5: QB | C5: No | D5: 1 | E5: Josh Allen | F5: BUF | G5: 24 | H5: 17 | I5: 38.8 | J5: 11.8 | K5: 23 | L5: 25.9 | M5: 20.4 | N5: 17.4 | O5: BYE | P5: 23.2 | Q5: 28.8 | R5: 20.3 | S5: 44.7 | T5: 10.1 | U5: 17.7 | V5: 37.8 | W5: 24.5 | X5: 6.9 | Y5: 23.2 | Z5: 0 | AA5: 22 | AB5: 374.6 | AC5: 374.6 | AD5: 1 | AE5: 15 | AF5: 13 | AG5: 11 | AH5: 5 | AI5: 3 | AJ5: 0.88235294 | AK5: 0.76470588 | AL5: 0.64705882 | AM5: 0.29411765 | AN5: 0.17647059

Sheet Detail2
A1: Details for Count of Round - Position: RB, Round: 1
A3: Year | B3: Position | C3: Rookie? | D3: RK | E3: Player | F3: Team | G3: ADP | H3: GP | I3: 1 | J3: 2 | K3: 3 | L3: 4 | M3: 5 | N3: 6 | O3: 7 | P3: 8 | Q3: 9 | R3: 10 | S3: 11 | T3: 12 | U3: 13 | V3: 14 | W3: 15 | X3: 16 | Y3: 17 | Z3: 18 | AA3: AVG | AB3: Total Points | AC3: TTL | AD3: Round | AE3: Boom 10 | AF3: Boom 15 | AG3: Boom 20 | AH3: Boom 25 | AI3: Boom 30 | AJ3: Boom 10% | AK3: Boom 15% | AL3: Boom 20% | AM3: Boom 25% | AN3: Boom 30%
A4: 2023 | B4: RB | C4: No | D4: 14 | E4: Tony Pollard | F4: DAL | G4: 15 | H4: 17 | I4: 22.2 | J4: 19.9 | K4: 15.1 | L4: 9 | M4: 8.4 | N4: 17 | O4: BYE | P4: 6.5 | Q4: 9.3 | R4: 5.5 | S4: 18 | T4: 22.3 | U4: 17.3 | V4: 16.6 | W4: 7.7 | X4: 5.3 | Y4: 5.9 | Z4: 16.6 | AA4: 13.1 | AB4: 206 | AC4: 222.6 | AD4: 1 | AE4: 8 | AF4: 9 | AG4: 2 | AH4: 0 | AI4: 0 | AJ4: 0.52941176 | AK4: 0.52941176 | AL4: 0.11764706 | AM4: 0 | AN4: 0
A5: 2023 | B5: RB | C5: No | D5: 1 | E5: Christian McCaffrey | F5: SF | G5: 2 | H5: 16 | I5: 25.9 | J5: 22.5 | K5: 22.9 | L5: 48.7 | M5: 13.8 | N5: 14.2 | O5: 22.6 | P5: 29.8 | Q5: BYE | R5: 20.2 | S5: 21.3 | T5: 30.9 | U5: 22.3 | V5: 16.3 | W5: 41.7 | X5: 25.1 | Y5: 13.1 | Z5: 0 | AA5: 24.5 | AB5: 391.3 | AC5: 391.3 | AD5: 1 | AE5: 16 | AF5: 13 | AG5: 12 | AH5: 6 | AI5: 3 | AJ5: 0.94117647 | AK5: 0.8125 | AL5: 0.75 | AM5: 0.375 | AN5: 0.1875
A6: 2024 | B6: RB | C6: No | D6: 69 | E6: Christian McCaffrey | F6: SF | G6: 1 | H6: 4 | I6: - | J6: - | K6: - | L6: - | M6: - | N6: - | O6: - | P6: - | Q6: BYE | R6: 16.7 | S6: 14.6 | T6: 7.8 | U6: 8.7 | V6: - | W6: - | X6: - | Y6: - | Z6: 0 | AA6: 12 | AB6: 47.8 | AC6: 47.8 | AD6: 1 | AE6: 2 | AF6: 1 | AG6: 0 | AH6: 0 | AI6: 0 | AJ6: 0.11764706 | AK6: 0.25 | AL6: 0 | AM6: 0 | AN6: 0
A7: 2024 | B7: RB | C7: No | D7: 16 | E7: Breece Hall | F7: NYJ | G7: 4 | H7: 16 | I7: 18.3 | J7: 24.4 | K7: 18.3 | L7: 3.8 | M7: 6.7 | N7: 21.9 | O7: 26.1 | P7: 9.9 | Q7: 10.5 | R7: 12.3 | S7: 31.1 | T7: BYE | U7: 6 | V7: - | W7: 13.1 | X7: 14 | Y7: 6.3 | Z7: 18.2 | AA7: 15.1 | AB7: 222.7 | AC7: 240.9 | AD7: 1 | AE7: 10 | AF7: 7 | AG7: 4 | AH7: 2 | AI7: 1 | AJ7: 0.64705882 | AK7: 0.4375 | AL7: 0.25 | AM7: 0.125 | AN7: 0.0625
A8: 2024 | B8: RB | C8: No | D8: 12 | E8: Jonathan Taylor | F8: IND | G8: 11 | H8: 14 | I8: 10.8 | J8: 15.5 | K8: 26.5 | L8: 19.8 | M8: - | N8: - | O8: - | P8: 18.7 | Q8: 8.9 | R8: 14.2 | S8: 7 | T8: 3.5 | U8: 17.3 | V8: BYE | W8: 10.1 | X8: 39.8 | Y8: 27.6 | Z8: 25 | AA8: 17.5 | AB8: 219.7 | AC8: 244.7 | AD8: 1 | AE8: 10 | AF8: 8 | AG8: 4 | AH8: 3 | AI8: 1 | AJ8: 0.64705882 | AK8: 0.57142857 | AL8: 0.28571429 | AM8: 0.21428571 | AN8: 0.071428571
A9: 2024 | B9: RB | C9: No | D9: 3 | E9: Bijan Robinson | F9: ATL | G9: 6 | H9: 17 | I9: 16.1 | J9: 16.2 | K9: 13.2 | L9: 11.4 | M9: 10.7 | N9: 25.5 | O9: 23.3 | P9: 23.6 | Q9: 21.5 | R9: 29.4 | S9: 10.3 | T9: BYE | U9: 25.5 | V9: 20.1 | W9: 14.5 | X9: 24.3 | Y9: 24.8 | Z9: 31.3 | AA9: 20.1 | AB9: 310.4 | AC9: 341.7 | AD9: 1 | AE9: 16 | AF9: 12 | AG9: 10 | AH9: 4 | AI9: 1 | AJ9: 1 | AK9: 0.70588235 | AL9: 0.58823529 | AM9: 0.23529412 | AN9: 0.058823529
A10: 2025 | B10: RB | C10: No | D10: 14 | E10: Saquon Barkley | F10: PHI | G10: 5 | H10: 16 | I10: 18.4 | J10: 17.4 | K10: 9.5 | L10: 17.4 | M10: 17.8 | N10: 8.7 | O10: 5.2 | P10: 33.4 | Q10: BYE | R10: 13.1 | S10: 10 | T10: 12.4 | U10: 5.6 | V10: 18.2 | W10: 17.2 | X10: 21.2 | Y10: 6.8 | Z10: 0 | AA10: 14.5 | AB10: 232.3 | AC10: 232.3 | AD10: 1 | AE10: 10 | AF10: 8 | AG10: 2 | AH10: 1 | AI10: 1 | AJ10: 0.58823529 | AK10: 0.5 | AL10: 0.125 | AM10: 0.0625 | AN10: 0.0625
A11: 2025 | B11: RB | C11: (R) | D11: 11 | E11: Ashton Jeanty | F11: LV | G11: 11 | H11: 17 | I11: 12 | J11: 7.4 | K11: 6.3 | L11: 33.5 | M11: 15.9 | N11: 16.6 | O11: 4.4 | P11: BYE | Q11: 19.9 | R11: 15.3 | S11: 9.4 | T11: 24.8 | U11: 12.1 | V11: 5.8 | W11: 8.2 | X11: 31.8 | Y11: 9.3 | Z11: 12.4 | AA11: 14.4 | AB11: 232.7 | AC11: 245.1 | AD11: 1 | AE11: 9 | AF11: 7 | AG11: 3 | AH11: 2 | AI11: 2 | AJ11: 0.58823529 | AK11: 0.41176471 | AL11: 0.17647059 | AM11: 0.11764706 | AN11: 0.11764706
A12: 2025 | B12: RB | C12: No | D12: 8 | E12: Derrick Henry | F12: BAL | G12: 12 | H12: 17 | I12: 29.2 | J12: 2.3 | K12: 10.7 | L12: 7.8 | M12: 9.3 | N12: 14 | O12: BYE | P12: 19.1 | Q12: 13.1 | R12: 11.4 | S12: 20.2 | T12: 22.8 | U12: 17.4 | V12: 11.2 | W12: 10 | X12: 22.8 | Y12: 45.6 | Z12: 12.6 | AA12: 16.4 | AB12: 266.9 | AC12: 279.5 | AD12: 1 | AE12: 12 | AF12: 7 | AG12: 5 | AH12: 2 | AI12: 1 | AJ12: 0.76470588 | AK12: 0.41176471 | AL12: 0.29411765 | AM12: 0.11764706 | AN12: 0.058823529
A13: 2025 | B13: RB | C13: No | D13: 3 | E13: Jahmyr Gibbs | F13: DET | G13: 3 | H13: 17 | I13: 15 | J13: 19.4 | K13: 26.9 | L13: 17.7 | M13: 16.7 | N13: 7.5 | O13: 36.8 | P13: BYE | Q13: 5.8 | R13: 38.2 | S13: 19.6 | T13: 55.4 | U13: 11.6 | V13: 37 | W13: 9.8 | X13: 22.8 | Y13: 6.4 | Z13: 20.3 | AA13: 21.6 | AB13: 346.6 | AC13: 366.9 | AD13: 1 | AE13: 12 | AF13: 11 | AG13: 7 | AH13: 5 | AI13: 4 | AJ13: 0.76470588 | AK13: 0.64705882 | AL13: 0.41176471 | AM13: 0.29411765 | AN13: 0.23529412
A14: 2025 | B14: RB | C14: No | D14: 2 | E14: Bijan Robinson | F14: ATL | G14: 2 | H14: 17 | I14: 24.4 | J14: 19.8 | K14: 16.1 | L14: 28.1 | M14: BYE | N14: 35.8 | O14: 21.2 | P14: 5.8 | Q14: 17.6 | R14: 10.8 | S14: 30.3 | T14: 14.7 | U14: 30.3 | V14: 9.4 | W14: 29.5 | X14: 29.8 | Y14: 39.9 | Z14: 7.3 | AA14: 21.8 | AB14: 363.5 | AC14: 370.8 | AD14: 1 | AE14: 14 | AF14: 12 | AG14: 9 | AH14: 7 | AI14: 4 | AJ14: 0.82352941 | AK14: 0.70588235 | AL14: 0.52941176 | AM14: 0.41176471 | AN14: 0.23529412
A15: 2025 | B15: RB | C15: No | D15: 1 | E15: Christian McCaffrey | F15: SF | G15: 7 | H15: 17 | I15: 23.2 | J15: 22.7 | K15: 24 | L15: 26.1 | M15: 27.9 | N15: 24.1 | O15: 39.1 | P15: 9.8 | Q15: 34.3 | R15: 17.6 | S15: 35.1 | T15: 27.2 | U15: 17.4 | V15: BYE | W15: 15.7 | X15: 32.6 | Y15: 28.1 | Z15: 11.7 | AA15: 24.5 | AB15: 404.9 | AC15: 416.6 | AD15: 1 | AE15: 15 | AF15: 15 | AG15: 12 | AH15: 8 | AI15: 4 | AJ15: 0.94117647 | AK15: 0.88235294 | AL15: 0.70588235 | AM15: 0.47058824 | AN15: 0.23529412

Sheet 2026 ADP
A1: Rank | B1: Player | C1: POS | D1: Team | E1: Bye
A2: 1 | B2: Jahmyr Gibbs | C2: RB1 | D2: DET | E2: 6
A3: 2 | B3: Bijan Robinson | C3: RB2 | D3: ATL | E3: 11
A4: 3 | B4: Ja'Marr Chase | C4: WR1 | D4: CIN | E4: 6
A5: 4 | B5: Puka Nacua | C5: WR2 | D5: LAR | E5: 11
A6: 5 | B6: Jaxon Smith-Njigba | C6: WR3 | D6: SEA | E6: 11
A7: 6 | B7: Christian McCaffrey | C7: RB3 | D7: SF | E7: 8
A8: 7 | B8: Amon-Ra St. Brown | C8: WR4 | D8: DET | E8: 6
A9: 8 | B9: Jonathan Taylor | C9: RB4 | D9: IND | E9: 13
A10: 9 | B10: James Cook III | C10: RB5 | D10: BUF | E10: 7
A11: 10 | B11: Ashton Jeanty | C11: RB6 | D11: LV | E11: 13
A12: 11 | B12: CeeDee Lamb | C12: WR5 | D12: DAL | E12: 14
A13: 12 | B13: Justin Jefferson | C13: WR6 | D13: MIN | E13: 6
... A254: 253 | B254: Tyquan Thornton | C254: WR99 | D254: KC | E254: 5
A255: 254 | B255: #N/A | C255: WR100 | D255: #N/A | E255: #N/A
A256: 255 | B256: Brandon Aiyuk | C256: WR101 | D256: SF | E256: 8
A257: 256 | B257: Jaylin Noel | C257: WR102 | D257: HOU | E257: 8
A258: 257 | B258: Eli Raridon | C258: TE39 | D258: NE | E258: 11
A259: 258 | B259: Jack Bech | C259: WR103 | D259: LV | E259: 13
A260: 259 | B260: Erick All Jr. | C260: TE40 | D260: CIN | E260: 6
A261: 260 | B261: Theo Johnson | C261: TE41 | D261: NYG | E261: 8
A262: 261 | B262: Elijah Sarratt | C262: WR104 | D262: BAL | E262: 13
A263: 262 | B263: Chimere Dike | C263: WR105 | D263: TEN | E263: 9
A264: 263 | B264: Najee Harris | C264: RB81 | D264: LAC | E264: 7
A265: 264 | B265: Tutu Atwell | C265: WR106 | D265: MIA | E265: 6
A266: 265 | B266: Elijah Arroyo | C266: TE42 | D266: SEA | E266: 11
A267: 266 | B267: Chris Brooks | C267: RB82 | D267: GB | E267: 11
... A273: 272 | B273: Zavion Thomas | C273: WR110 | D273: CHI | E273: 10
A274: 273 | B274: #N/A | C274: RB83 | D274: #N/A | E274: #N/A
A275: 274 | B275: Malik Benson | C275: WR111 | D275: LV | E275: 13
A276: 275 | B276: Roman Wilson | C276: WR112 | D276: PIT | E276: 9
A277: 276 | B277: Demarcus Robinson | C277: WR113 | D277: SF | E277: 8
A278: 277 | B278: Joshua Palmer | C278: WR114 | D278: BUF | E278: 7
A279: 278 | B279: Brenen Thompson | C279: WR115 | D279: LAC | E279: 7
A280: 279 | B280: Kalif Raymond | C280: WR116 | D280: CHI | E280: 10
A281: 280 | B281: DeMario Douglas | C281: WR117 | D281: NE | E281: 11
A282: 281 | B282: #N/A | C282: RB84 | D282: #N/A | E282: #N/A
A283: 282 | B283: Devontez Walker | C283: WR118 | D283: BAL | E283: 13
A284: 283 | B284: Bryce Lance | C284: WR119 | D284: NO | E284: 8
A285: 284 | B285: Joe Flacco | C285: QB37 | D285: CIN | E285: 6
...

Sheet Positions By round
B1: Round | C1: Qb | D1: RB | E1: WR | F1: TE
B2: 1 | C2: 0 | D2: 6 | E2: 6 | F2: 0
B3: 2 | C3: 0 | D3: 13 | E3: 10 | F3: 1
B4: 3 | C4: 1 | D4: 16 | E4: 17 | F4: 2
B5: 4 | C5: 2 | D5: 18 | E5: 25 | F5: 3
B6: 5 | C6: 5 | D6: 23 | E6: 29 | F6: 3
B7: 6 | C7: 8 | D7: 26 | E7: 33 | F7: 5
B8: 7 | C8: 10 | D8: 38 | E8: 30 | F8: 6
B9: 8 | C9: 13 | D9: 32 | E9: 43 | F9: 8
B10: 9 | C10: 16 | D10: 34 | E10: 47 | F10: 11
B11: 10 | C11: 19 | D11: 40 | E11: 49 | F11: 12
B12: 11 | C12: 22 | D12: 41 | E12: 53 | F12: 16
B13: 12 | C13: 23 | D13: 48 | E13: 58 | F13: 19
... B17: 16 | C17: 29 | D17: 60 | E17: 78 | F17: 29

Sheet 22-25
A1: Year | B1: Position | C1: Rookie? | D1: RK | E1: Player | F1: Team | G1: ADP | H1: GP | I1: 1 | J1: 2 | K1: 3 | L1: 4 | M1: 5 | N1: 6 | O1: 7 | P1: 8 | Q1: 9 | R1: 10 | S1: 11 | T1: 12 | U1: 13 | V1: 14 | W1: 15 | X1: 16 | Y1: 17 | Z1: 18 | AA1: AVG | AB1: Total Points | AC1: TTL | AD1: Round | AE1: Boom 10 | AF1: Boom 15 | AG1: Boom 20 | AH1: Boom 25 | AI1: Boom 30 | AJ1: Boom 10% | AK1: Boom 15% | AL1: Boom 20% | AM1: Boom 25% | AN1: Boom 30%
A2: 2025 | B2: TE | C2: =IF(COUNTIF('Rookies 22-25'!$B$198:$B$349,E2)>0,"(R)","No") -> No | D2: 1 | E2: Trey McBride | F2: ARI | G2: =VLOOKUP(E2,'25 Draft ADP'!$B$3:$D$505,3,FALSE) -> 25 | H2: 17 | I2: 12.1 | J2: 13.8 | K2: 15.3 | L2: 12.2 | M2: 9.1 | N2: 21.2 | O2: 29.4 | P2: BYE | Q2: 16.5 | R2: 27.7 | S2: 27.5 | T2: 16.9 | U2: 22.2 | V2: 10.8 | W2: 37.4 | X2: 6.7 | Y2: 23.6 | Z2: 13.5 | AA2: 18.6 | AB2: =AC2-Z2 -> 302.4 | AC2: 315.9 | AD2: 3 | AE2: =COUNTIF(I2:Y2,">10") -> 14 | AF2: 10 | AG2: 7 | AH2: 4 | AI2: 1 | AJ2: 0.88235294 | AK2: 0.58823529 | AL2: 0.41176471 | AM2: 0.23529412 | AN2: 0.058823529
A3: 2025 | B3: TE | C3: =IF(COUNTIF('Rookies 22-25'!$B$198:$B$349,E3)>0,"(R)","No") -> No | D3: 2 | E3: Kyle Pitts Sr. | F3: ATL | G3: =VLOOKUP(E3,'25 Draft ADP'!$B$3:$D$505,3,FALSE) -> 139 | H3: 17 | I3: 12.9 | J3: 7.7 | K3: 7.9 | L3: 18 | M3: BYE | N3: 4.8 | O3: 13.2 | P3: 14.9 | Q3: 7.8 | R3: 5.8 | S3: 3.4 | T3: 4.5 | U3: 15.2 | V3: 15 | W3: 45.6 | X3: 18.7 | Y3: 3.6 | Z3: 11.8 | AA3: 12.4 | AB3: =AC3-Z3 -> 199 | AC3: 210.8 | AD3: 11 | AE3: =COUNTIF(I3:Y3,">10") -> 8 | AF3: 4 | AG3: 1 | AH3: 1 | AI3: 1 | AJ3: 0.52941176 | AK3: 0.23529412 | AL3: 0.058823529 | AM3: 0.058823529 | AN3: 0.058823529
A4: 2025 | B4: TE | C4: =IF(COUNTIF('Rookies 22-25'!$B$198:$B$349,E4)>0,"(R)","No") -> No | D4: 3 | E4: Travis Kelce | F4: KC | G4: =VLOOKUP(E4,'25 Draft ADP'!$B$3:$D$505,3,FALSE) -> 77 | H4: 17 | I4: 12.7 | J4: 10.1 | K4: 6.6 | L4: 9.8 | M4: 19.1 | N4: 13.8 | O4: 8.4 | P4: 21.9 | Q4: 12.6 | R4: BYE | S4: 24.1 | T4: 8.4 | U4: 15.5 | V4: 1.8 | W4: 14 | X4: 1.6 | Y4: 8.6 | Z4: 4.2 | AA4: 11.4 | AB4: =AC4-Z4 -> 189 | AC4: 193.2 | AD4: 7 | AE4: =COUNTIF(I4:Y4,">10") -> 9 | AF4: 4 | AG4: 2 | AH4: 0 | AI4: 0 | AJ4: 0.52941176 | AK4: 0.23529412 | AL4: 0.11764706 | AM4: 0 | AN4: 0
A5: 2025 | B5: TE | C5: =IF(COUNTIF('Rookies 22-25'!$B$198:$B$349,E5)>0,"(R)","No") -> (R) | D5: 4 | E5: Tyler Warren | F5: IND | G5: =VLOOKUP(E5,'25 Draft ADP'!$B$3:$D$505,3,FALSE) -> 87 | H5: 17 | I5: 14.9 | J5: 11.9 | K5: 6.8 | L5: 18.3 | M5: 14.4 | N5: 18.3 | O5: 16.9 | P5: 9.3 | Q5: 7.6 | R5: 17.9 | S5: BYE | T5: 9.5 | U5: 11.2 | V5: 3.7 | W5: 4.9 | X5: 6 | Y5: 9.3 | Z5: 7.6 | AA5: 11.1 | AB5: =AC5-Z5 -> 180.9 | AC5: 188.5 | AD5: 7 | AE5: =COUNTIF(I5:Y5,">10") -> 8 | AF5: 4 | AG5: 0 | AH5: 0 | AI5: 0 | AJ5: 0.47058824 | AK5: 0.23529412 | AL5: 0 | AM5: 0 | AN5: 0
A6: 2025 | B6: TE | C6: =IF(COUNTIF('Rookies 22-25'!$B$198:$B$349,E6)>0,"(R)","No") -> No | D6: 5 | E6: Jake Ferguson | F6: DAL | G6: =VLOOKUP(E6,'25 Draft ADP'!$B$3:$D$505,3,FALSE) -> 131 | H6: 17 | I6: 7.3 | J6: 16.8 | K6: 21.2 | L6: 17 | M6: 23.9 | N6: 12.3 | O6: 21.9 | P6: 0 | Q6: 8 | R6: BYE | S6: 11.6 | T6: 11.1 | U6: 8.6 | V6: 10.8 | W6: 3.6 | X6: 4.9 | Y6: 7.6 | Z6: 1.5 | AA6: 11.1 | AB6: =AC6-Z6 -> 186.6 | AC6: 188.1 | AD6: 12 | AE6: =COUNTIF(I6:Y6,">10") -> 9 | AF6: 5 | AG6: 3 | AH6: 0 | AI6: 0 | AJ6: 0.52941176 | AK6: 0.29411765 | AL6: 0.17647059 | AM6: 0 | AN6: 0
A7: 2025 | B7: TE | C7: =IF(COUNTIF('Rookies 22-25'!$B$198:$B$349,E7)>0,"(R)","No") -> (R) | D7: 6 | E7: Harold Fannin Jr. | F7: CLE | G7: =VLOOKUP(E7,'25 Draft ADP'!$B$3:$D$505,3,FALSE) -> 207 | H7: 16 | I7: 13.6 | J7: 9.8 | K7: 5.5 | L7: 4.5 | M7: 11.3 | N7: 15.1 | O7: 7.6 | P7: 18.4 | Q7: BYE | R7: 8.4 | S7: 4.6 | T7: 8.4 | U7: 11.3 | V7: 25.4 | W7: 12 | X7: 19.5 | Y7: 11 | Z7: 0 | AA7: 11.7 | AB7: =AC7-Z7 -> 186.4 | AC7: 186.4 | AD7: 18 | AE7: =COUNTIF(I7:Y7,">10") -> 9 | AF7: 4 | AG7: 1 | AH7: 1 | AI7: 0 | AJ7: 0.52941176 | AK7: 0.25 | AL7: 0.0625 | AM7: 0.0625 | AN7: 0
A8: 2025 | B8: TE | C8: =IF(COUNTIF('Rookies 22-25'!$B$198:$B$349,E8)>0,"(R)","No") -> No | D8: 7 | E8: Dallas Goedert | F8: PHI | G8: =VLOOKUP(E8,'25 Draft ADP'!$B$3:$D$505,3,FALSE) -> 142 | H8: 15 | I8: 11.4 | J8: - | K8: 10.3 | L8: 19.7 | M8: 10.9 | N8: 26 | O8: 4.8 | P8: 17.8 | Q8: BYE | R8: 8.3 | S8: 4.4 | T8: 4 | U8: 4.7 | V8: 15.8 | W8: 25 | X8: 12.2 | Y8: 9.8 | Z8: 0 | AA8: 12.3 | AB8: =AC8-Z8 -> 185.1 | AC8: 185.1 | AD8: 12 | AE8: =COUNTIF(I8:Y8,">10") -> 9 | AF8: 5 | AG8: 2 | AH8: 1 | AI8: 0 | AJ8: 0.52941176 | AK8: 0.33333333 | AL8: 0.13333333 | AM8: 0.066666667 | AN8: 0
A9: 2025 | B9: TE | C9: =IF(COUNTIF('Rookies 22-25'!$B$198:$B$349,E9)>0,"(R)","No") -> No | D9: 8 | E9: Juwan Johnson | F9: NO | G9: =VLOOKUP(E9,'25 Draft ADP'!$B$3:$D$505,3,FALSE) -> 216 | H9: 17 | I9: 15.6 | J9: 15.9 | K9: 11.1 | L9: 5.8 | M9: 3.7 | N9: 1.5 | O9: 12.9 | P9: 10.3 | Q9: 12.1 | R9: 19.2 | S9: BYE | T9: 10.6 | U9: 8.9 | V9: 7.8 | W9: 7 | X9: 16.9 | Y9: 13.5 | Z9: 7.1 | AA9: 10.6 | AB9: =AC9-Z9 -> 172.8 | AC9: 179.9 | AD9: 19 | AE9: =COUNTIF(I9:Y9,">10") -> 10 | AF9: 4 | AG9: 0 | AH9: 0 | AI9: 0 | AJ9: 0.58823529 | AK9: 0.23529412 | AL9: 0 | AM9: 0 | AN9: 0
A10: 2025 | B10: TE | C10: =IF(COUNTIF('Rookies 22-25'!$B$198:$B$349,E10)>0,"(R)","No") -> No | D10: 9 | E10: Hunter Henry | F10: NE | G10: =VLOOKUP(E10,'25 Draft ADP'!$B$3:$D$505,3,FALSE) -> 160 | H10: 17 | I10: 10.6 | J10: 1.9 | K10: 29 | L10: 11.9 | M10: 6.6 | N10: 5.7 | O10: 7.3 | P10: 7.7 | Q10: 9.1 | R10: 1.9 | S10: 8.5 | T10: 24.5 | U10: 11.3 | V10: BYE | W10: 2.8 | X10: 15.5 | Y10: 13.9 | Z10: 10.6 | AA10: 10.5 | AB10: =AC10-Z10 -> 168.2 | AC10: 178.8 | AD10: 14 | AE10: =COUNTIF(I10:Y10,">10") -> 7 | AF10: 3 | AG10: 2 | AH10: 1 | AI10: 0 | AJ10: 0.47058824 | AK10: 0.17647059 | AL10: 0.11764706 | AM10: 0.058823529 | AN10: 0
A11: 2025 | B11: TE | C11: =IF(COUNTIF('Rookies 22-25'!$B$198:$B$349,E11)>0,"(R)","No") -> No | D11: 10 | E11: Dalton Schultz | F11: HOU | G11: =VLOOKUP(E11,'25 Draft ADP'!$B$3:$D$505,3,FALSE) -> 217 | H11: 17 | I11: 5.8 | J11: 5.9 | K11: 8.9 | L11: 8 | M11: 11 | N11: BYE | O11: 18.8 | P11: 4.4 | Q11: 13.7 | R11: 18.3 | S11: 11.1 | T11: 1.8 | U11: 12.5 | V11: 5.2 | W11: 21.6 | X11: 14.5 | Y11: 4.9 | Z11: 11.3 | AA11: 10.5 | AB11: =AC11-Z11 -> 166.4 | AC11: 177.7 | AD11: 19 | AE11: =COUNTIF(I11:Y11,">10") -> 8 | AF11: 3 | AG11: 1 | AH11: 0 | AI11: 0 | AJ11: 0.52941176 | AK11: 0.17647059 | AL11: 0.058823529 | AM11: 0 | AN11: 0
A12: 2025 | B12: TE | C12: =IF(COUNTIF('Rookies 22-25'!$B$198:$B$349,E12)>0,"(R)","No") -> No | D12: 11 | E12: Brock Bowers | F12: LV | G12: =VLOOKUP(E12,'25 Draft ADP'!$B$3:$D$505,3,FALSE) -> 18 | H12: 12 | I12: 15.3 | J12: 8.8 | K12: 9.8 | L12: 9.6 | M12: - | N12: - | O12: - | P12: BYE | Q12: 43.3 | R12: 3.7 | S12: 14.2 | T12: 11.5 | U12: 22.3 | V12: 14.6 | W12: 8.8 | X12: 14.3 | Y12: - | Z12: 0 | AA12: 14.7 | AB12: =AC12-Z12 -> 176.2 | AC12: 176.2 | AD12: 2 | AE12: =COUNTIF(I12:Y12,">10") -> 7 | AF12: 3 | AG12: 2 | AH12: 1 | AI12: 1 | AJ12: 0.41176471 | AK12: 0.25 | AL12: 0.16666667 | AM12: 0.083333333 | AN12: 0.083333333
A13: 2025 | B13: TE | C13: =IF(COUNTIF('Rookies 22-25'!$B$198:$B$349,E13)>0,"(R)","No") -> (R) | D13: 12 | E13: Colston Loveland | F13: CHI | G13: =VLOOKUP(E13,'25 Draft ADP'!$B$3:$D$505,3,FALSE) -> 110 | H13: 16 | I13: 3.2 | J13: 0 | K13: 4.1 | L13: - | M13: BYE | N13: 3.1 | O13: 5.4 | P13: 6.8 | Q13: 29.8 | R13: 9.5 | S13: 7 | T13: 14.9 | U13: 5.8 | V13: 12.9 | W13: 10.1 | X13: 6 | Y13: 21.4 | Z13: 25.1 | AA13: 10.3 | AB13: =AC13-Z13 -> 140 | AC13: 165.1 | AD13: 9 | AE13: =COUNTIF(I13:Y13,">10") -> 5 | AF13: 3 | AG13: 3 | AH13: 2 | AI13: 0 | AJ13: 0.35294118 | AK13: 0.1875 | AL13: 0.1875 | AM13: 0.125 | AN13: 0
A14: 2025 | B14: TE | C14: =IF(COUNTIF('Rookies 22-25'!$B$198:$B$349,E14)>0,"(R)","No") -> No | D14: 13 | E14: George Kittle | F14: SF | G14: =VLOOKUP(E14,'25 Draft ADP'!$B$3:$D$505,3,FALSE) -> 35 | H14: 11 | I14: 12.5 | J14: - | K14: - | L14: - | M14: - | N14: - | O14: 0 | P14: 14.3 | Q14: 6.9 | R14: 23.4 | S14: 24.7 | T14: 13.8 | U14: 10.7 | V14: BYE | W14: 22.8 | X14: 24.5 | Y14: - | Z14: 7.9 | AA14: 14.7 | AB14: =AC14-Z14 -> 153.6 | AC14: 161.5 | AD14: 3 | AE14: =COUNTIF(I14:Y14,">10") -> 8 | AF14: 4 | AG14: 4 | AH14: 0 | AI14: 0 | AJ14: 0.47058824 | AK14: 0.36363636 | AL14: 0.36363636 | AM14: 0 | AN14: 0
A15: 2025 | B15: TE | C15: =IF(COUNTIF('Rookies 22-25'!$B$198:$B$349,E15)>0,"(R)","No") -> No | D15: 14 | E15: AJ Barner | F15: SEA | G15: =VLOOKUP(E15,'25 Draft ADP'!$B$3:$D$505,3,FALSE) -> 278 | H15: 17 | I15: 1.2 | J15: 10.8 | K15: 3.3 | L15: 12.2 | M15: 24.3 | N15: 10.1 | O15: 1.9 | P15: BYE | Q15: 11.5 | R15: 0.3 | S15: 17.1 | T15: 3.8 | U15: 7.7 | V15: 5.7 | W15: 5.7 | X15: 15 | Y15: 13.3 | Z15: 3.4 | AA15: 8.7 | AB15: =AC15-Z15 -> 143.9 | AC15: 147.3 | AD15: 20 | AE15: =COUNTIF(I15:Y15,">10") -> 8 | AF15: 2 | AG15: 1 | AH15: 0 | AI15: 0 | AJ15: 0.47058824 | AK15: 0.11764706 | AL15: 0.058823529 | AM15: 0 | AN15: 0
A16: 2025 | B16: TE | C16: =IF(COUNTIF('Rookies 22-25'!$B$198:$B$349,E16)>0,"(R)","No") -> (R) | D16: 15 | E16: Oronde Gadsden II | F16: LAC | G16: =VLOOKUP(E16,'25 Draft ADP'!$B$3:$D$505,3,FALSE) -> 277 | H16: 15 | I16: - | J16: - | K16: 9.6 | L16: 3.6 | M16: 2.4 | N16: 11.8 | O16: 29.4 | P16: 18.7 | Q16: 11.8 | R16: 4.3 | S16: 6.1 | T16: BYE | U16: 3.7 | V16: 1.7 | W16: 10.1 | X16: 1.7 | Y16: 12.2 | Z16: 4.3 | AA16: 8.8 | AB16: =AC16-Z16 -> 127.1 | AC16: 131.4 | AD16: 20 | AE16: =COUNTIF(I16:Y16,">10") -> 6 | AF16: 2 | AG16: 1 | AH16: 1 | AI16: 0 | AJ16: 0.35294118 | AK16: 0.13333333 | AL16: 0.066666667 | AM16: 0.066666667 | AN16: 0
A17: 2025 | B17: TE | C17: =IF(COUNTIF('Rookies 22-25'!$B$198:$B$349,E17)>0,"(R)","No") -> No | D17: 16 | E17: Mark Andrews | F17: BAL | G17: =VLOOKUP(E17,'25 Draft ADP'!$B$3:$D$505,3,FALSE) -> 94 | H17: 17 | I17: 1.5 | J17: 1.4 | K17: 27.1 | L17: 10 | M17: 4.2 | N17: 6.6 | O17: BYE | P17: 6.4 | Q17: 16.6 | R17: 10.4 | S17: 15.7 | T17: 2.1 | U17: 8.7 | V17: 1.9 | W17: 3.8 | X17: 4.4 | Y17: 6.8 | Z17: 3.4 | AA17: 7.7 | AB17: =AC17-Z17 -> 127.6 | AC17: 131 | AD17: 9 | AE17: =COUNTIF(I17:Y17,">10") -> 4 | AF17: 3 | AG17: 1 | AH17: 1 | AI17: 0 | AJ17: 0.23529412 | AK17: 0.17647059 | AL17: 0.058823529 | AM17: 0.058823529 | AN17: 0
A18: 2025 | B18: TE | C18: =IF(COUNTIF('Rookies 22-25'!$B$198:$B$349,E18)>0,"(R)","No") -> No | D18: 17 | E18: Colby Parkinson | F18: LAR | G18: =VLOOKUP(E18,'25 Draft ADP'!$B$3:$D$505,3,FALSE) -> 408 | H18: 15 | I18: -0.6 | J18: - | K18: 0 | L18: 3.7 | M18: 0 | N18: - | O18: 7.7 | P18: BYE | Q18: 3 | R18: 14.1 | S18: 9.4 | T18: 14.1 | U18: 6.7 | V18: 12.2 | W18: 24.5 | X18: 4.1 | Y18: 11.3 | Z18: 19.6 | AA18: 8.7 | AB18: =AC18-Z18 -> 110.2 | AC18: 129.8 | AD18: 20 | AE18: =COUNTIF(I18:Y18,">10") -> 5 | AF18: 2 | AG18: 1 | AH18: 0 | AI18: 0 | AJ18: 0.35294118 | AK18: 0.13333333 | AL18: 0.066666667 | AM18: 0 | AN18: 0
A19: 2025 | B19: TE | C19: =IF(COUNTIF('Rookies 22-25'!$B$198:$B$349,E19)>0,"(R)","No") -> No | D19: 18 | E19: Theo Johnson | F19: NYG | G19: =VLOOKUP(E19,'25 Draft ADP'!$B$3:$D$505,3,FALSE) -> 204 | H19: 15 | I19: 1.5 | J19: 7.4 | K19: 2 | L19: 10.7 | M19: 21.3 | N19: 4.7 | O19: 15.6 | P19: 5 | Q19: 11.7 | R19: 14.5 | S19: 6.6 | T19: 10.7 | U19: 5.9 | V19: BYE | W19: 10.2 | X19: 0 | Y19: - | Z19: 0 | AA19: 8.5 | AB19: =AC19-Z19 -> 127.8 | AC19: 127.8 | AD19: 18 | AE19: =COUNTIF(I19:Y19,">10") -> 7 | AF19: 2 | AG19: 1 | AH19: 0 | AI19: 0 | AJ19: 0.41176471 | AK19: 0.13333333 | AL19: 0.066666667 | AM19: 0 | AN19: 0
A20: 2025 | B20: TE | C20: =IF(COUNTIF('Rookies 22-25'!$B$198:$B$349,E20)>0,"(R)","No") -> No | D20: 19 | E20: Zach Ertz | F20: WAS | G20: =VLOOKUP(E20,'25 Draft ADP'!$B$3:$D$505,3,FALSE) -> 154 | H20: 13 | I20: 11.6 | J20: 18.4 | K20: 6.8 | L20: 6.1 | M20: 0 | N20: 16.3 | O20: 12.7 | P20: 5.6 | Q20: 8.6 | R20: 9.4 | S20: 8.2 | T20: BYE | U20: 20.6 | V20: 2.1 | W20: - | X20: - | Y20: - | Z20: 0 | AA20: 9.7 | AB20: =AC20-Z20 -> 126.4 | AC20: 126.4 | AD20: 13 | AE20: =COUNTIF(I20:Y20,">10") -> 5 | AF20: 3 | AG20: 1 | AH20: 0 | AI20: 0 | AJ20: 0.29411765 | AK20: 0.23076923 | AL20: 0.076923077 | AM20: 0 | AN20: 0
A21: 2025 | B21: TE | C21: =IF(COUNTIF('Rookies 22-25'!$B$198:$B$349,E21)>0,"(R)","No") -> No | D21: 20 | E21: Dalton Kincaid | F21: BUF | G21: =VLOOKUP(E21,'25 Draft ADP'!$B$3:$D$505,3,FALSE) -> 130 | H21: 12 | I21: 14.8 | J21: 7.7 | K21: 17.6 | L21: 9.8 | M21: 16.8 | N21: - | O21: BYE | P21: 3.3 | Q21: 22.1 | R21: 5.7 | S21: - | T21: - | U21: - | V21: 14.1 | W21: 6.4 | X21: 0 | Y21: - | Z21: 7.8 | AA21: 10.5 | AB21: =AC21-Z21 -> 118.3 | AC21: 126.1 | AD21: 11 | AE21: =COUNTIF(I21:Y21,">10") -> 5 | AF21: 3 | AG21: 1 | AH21: 0 | AI21: 0 | AJ21: 0.29411765 | AK21: 0.25 | AL21: 0.083333333 | AM21: 0 | AN21: 0
A22: 2025 | B22: TE | C22: =IF(COUNTIF('Rookies 22-25'!$B$198:$B$349,E22)>0,"(R)","No") -> No | D22: 21 | E22: Chig Okonkwo | F22: TEN | G22: =VLOOKUP(E22,'25 Draft ADP'!$B$3:$D$505,3,FALSE) -> 165 | H22: 17 | I22: 4.9 | J22: 7.5 | K22: 11.6 | L22: 1.4 | M22: 8.8 | N22: 10.6 | O22: 0 | P22: 9.3 | Q22: 3 | R22: BYE | S22: 8.6 | T22: 7 | U22: 6.9 | V22: 4 | W22: 7.3 | X22: 16.4 | Y22: 14.5 | Z22: 2.2 | AA22: 7.3 | AB22: =AC22-Z22 -> 121.8 | AC22: 124 | AD22: 15 | AE22: =COUNTIF(I22:Y22,">10") -> 4 | AF22: 1 | AG22: 0 | AH22: 0 | AI22: 0 | AJ22: 0.23529412 | AK22: 0.058823529 | AL22: 0 | AM22: 0 | AN22: 0
A23: 2025 | B23: TE | C23: =IF(COUNTIF('Rookies 22-25'!$B$198:$B$349,E23)>0,"(R)","No") -> No | D23: 22 | E23: Cade Otton | F23: TB | G23: =VLOOKUP(E23,'25 Draft ADP'!$B$3:$D$505,3,FALSE) -> 179 | H23: 16 | I23: 0 | J23: 5.5 | K23: 0 | L23: 3.9 | M23: 12.1 | N23: 10.1 | O23: 13.5 | P23: 8 | Q23: BYE | R23: 17.2 | S23: 4.8 | T23: 6.1 | U23: 2.9 | V23: 4.9 | W23: - | X23: 3.5 | Y23: 7.3 | Z23: 22.4 | AA23: 7.6 | AB23: =AC23-Z23 -> 99.8 | AC23: 122.2 | AD23: 16 | AE23: =COUNTIF(I23:Y23,">10") -> 4 | AF23: 2 | AG23: 1 | AH23: 0 | AI23: 0 | AJ23: 0.29411765 | AK23: 0.125 | AL23: 0.0625 | AM23: 0 | AN23: 0
A24: 2025 | B24: TE | C24: =IF(COUNTIF('Rookies 22-25'!$B$198:$B$349,E24)>0,"(R)","No") -> No | D24: 23 | E24: Brenton Strange | F24: JAC | G24: =VLOOKUP(E24,'25 Draft ADP'!$B$3:$D$505,3,FALSE) -> 159 | H24: 12 | I24: 9.9 | J24: 4.7 | K24: 12.1 | L24: 10.5 | M24: 3.2 | N24: - | O24: - | P24: BYE | Q24: - | R24: - | S24: - | T24: 14.3 | U24: 13.5 | V24: 5.7 | W24: 3.6 | X24: 14.9 | Y24: 8.4 | Z24: 17.2 | AA24: 9.8 | AB24: =AC24-Z24 -> 100.8 | AC24: 118 | AD24: 13 | AE24: =COUNTIF(I24:Y24,">10") -> 5 | AF24: 1 | AG24: 0 | AH24: 0 | AI24: 0 | AJ24: 0.35294118 | AK24: 0.083333333 | AL24: 0 | AM24: 0 | AN24: 0
A25: 2025 | B25: TE | C25: =IF(COUNTIF('Rookies 22-25'!$B$198:$B$349,E25)>0,"(R)","No") -> No | D25: 24 | E25: Tucker Kraft | F25: GB | G25: =VLOOKUP(E25,'25 Draft ADP'!$B$3:$D$505,3,FALSE) -> 107 | H25: 8 | I25: 9.9 | J25: 24.4 | K25: 5.9 | L25: 10.6 | M25: BYE | N25: 12.3 | O25: 16.8 | P25: 33.3 | Q25: 4 | R25: - | S25: - | T25: - | U25: - | V25: - | W25: - | X25: - | Y25: - | Z25: 0 | AA25: 14.7 | AB25: =AC25-Z25 -> 117.2 | AC25: 117.2 | AD25: 10 | AE25: =COUNTIF(I25:Y25,">10") -> 5 | AF25: 3 | AG25: 2 | AH25: 1 | AI25: 1 | AJ25: 0.29411765 | AK25: 0.375 | AL25: 0.25 | AM25: 0.125 | AN25: 0.125
A26: 2025 | B26: TE | C26: =IF(COUNTIF('Rookies 22-25'!$B$198:$B$349,E26)>0,"(R)","No") -> No | D26: 25 | E26: Pat Freiermuth | F26: PIT | G26: =VLOOKUP(E26,'25 Draft ADP'!$B$3:$D$505,3,FALSE) -> 209 | H26: 17 | I26: 5.8 | J26: 6.1 | K26: 1.6 | L26: 0 | M26: BYE | N26: 2.1 | O26: 28.1 | P26: 4.3 | Q26: 11.7 | R26: 6.3 | S26: 2.9 | T26: 10.9 | U26: 0 | V26: 2.9 | W26: 7.5 | X26: 6 | Y26: 9.3 | Z26: 8.1 | AA26: 6.7 | AB26: =AC26-Z26 -> 105.5 | AC26: 113.6 | AD26: 18 | AE26: =COUNTIF(I26:Y26,">10") -> 3 | AF26: 1 | AG26: 1 | AH26: 1 | AI26: 0 | AJ26: 0.17647059 | AK26: 0.058823529 | AL26: 0.058823529 | AM26: 0.058823529 | AN26: 0
A27: 2025 | B27: TE | C27: =IF(COUNTIF('Rookies 22-25'!$B$198:$B$349,E27)>0,"(R)","No") -> No | D27: 26 | E27: T.J. Hockenson | F27: MIN | G27: =VLOOKUP(E27,'25 Draft ADP'!$B$3:$D$505,3,FALSE) -> 83 | H27: 15 | I27: 4.5 | J27: 2.2 | K27: 15.9 | L27: 7.9 | M27: 9.8 | N27: BYE | O27: 10.3 | P27: 4.6 | Q27: 9.1 | R27: 2.8 | S27: 6.9 | T27: 5.9 | U27: 11.9 | V27: 9.2 | W27: 10.6 | X27: 1.2 | Y27: - | Z27: 0 | AA27: 7.5 | AB27: =AC27-Z27 -> 112.8 | AC27: 112.8 | AD27: 7 | AE27: =COUNTIF(I27:Y27,">10") -> 4 | AF27: 1 | AG27: 0 | AH27: 0 | AI27: 0 | AJ27: 0.23529412 | AK27: 0.066666667 | AL27: 0 | AM27: 0 | AN27: 0
A28: 2025 | B28: TE | C28: =IF(COUNTIF('Rookies 22-25'!$B$198:$B$349,E28)>0,"(R)","No") -> No | D28: 27 | E28: Sam LaPorta | F28: DET | G28: =VLOOKUP(E28,'25 Draft ADP'!$B$3:$D$505,3,FALSE) -> 68 | H28: 9 | I28: 13.9 | J28: 5.6 | K28: 7.3 | L28: 6.9 | M28: 20.2 | N28: 16.5 | O28: 4.5 | P28: BYE | Q28: 21.7 | R28: 10.3 | S28: - | T28: - | U28: - | V28: - | W28: - | X28: - | Y28: - | Z28: 0 | AA28: 11.9 | AB28: =AC28-Z28 -> 106.9 | AC28: 106.9 | AD28: 6 | AE28: =COUNTIF(I28:Y28,">10") -> 5 | AF28: 3 | AG28: 2 | AH28: 0 | AI28: 0 | AJ28: 0.29411765 | AK28: 0.33333333 | AL28: 0.22222222 | AM28: 0 | AN28: 0
A29: 2025 | B29: TE | C29: =IF(COUNTIF('Rookies 22-25'!$B$198:$B$349,E29)>0,"(R)","No") -> No | D29: 28 | E29: Dawson Knox | F29: BUF | G29: =VLOOKUP(E29,'25 Draft ADP'!$B$3:$D$505,3,FALSE) -> 300 | H29: 17 | I29: 4 | J29: 3.9 | K29: 0 | L29: 0 | M29: 3.5 | N29: 8.9 | O29: BYE | P29: 2.5 | Q29: 4 | R29: 6.7 | S29: 3.3 | T29: 4.7 | U29: 5.8 | V29: 17.3 | W29: 18.7 | X29: 2 | Y29: 8 | Z29: 10.4 | AA29: 6.1 | AB29: =AC29-Z29 -> 93.3 | AC29: 103.7 | AD29: 20 | AE29: =COUNTIF(I29:Y29,">10") -> 2 | AF29: 2 | AG29: 0 | AH29: 0 | AI29: 0 | AJ29: 0.17647059 | AK29: 0.11764706 | AL29: 0 | AM29: 0 | AN29: 0
A30: 2025 | B30: TE | C30: =IF(COUNTIF('Rookies 22-25'!$B$198:$B$349,E30)>0,"(R)","No") -> No | D30: 29 | E30: Evan Engram | F30: DEN | G30: =VLOOKUP(E30,'25 Draft ADP'!$B$3:$D$505,3,FALSE) -> 99 | H30: 16 | I30: 5.1 | J30: 2.2 | K30: - | L30: 6.9 | M30: 13.3 | N30: 9.9 | O30: 9.2 | P30: 7.6 | Q30: 0 | R30: 3.2 | S30: 7.3 | T30: BYE | U30: 13.9 | V30: 2.8 | W30: 2.2 | X30: 5.6 | Y30: 6.1 | Z30: 7.5 | AA30: 6.4 | AB30: =AC30-Z30 -> 95.3 | AC30: 102.8 | AD30: 8 | AE30: =COUNTIF(I30:Y30,">10") -> 2 | AF30: 0 | AG30: 0 | AH30: 0 | AI30: 0 | AJ30: 0.11764706 | AK30: 0 | AL30: 0 | AM30: 0 | AN30: 0
A31: 2025 | B31: TE | C31: =IF(COUNTIF('Rookies 22-25'!$B$198:$B$349,E31)>0,"(R)","No") -> No | D31: 30 | E31: Jake Tonges | F31: SF | G31: 300 | H31: 16 | I31: 10.5 | J31: 7.1 | K31: 4.1 | L31: 14.8 | M31: 17.1 | N31: 11.8 | O31: 0 | P31: 7.2 | Q31: 0 | R31: 0 | S31: 0 | T31: 0 | U31: 0 | V31: BYE | W31: 0 | X31: 1.7 | Y31: 19 | Z31: 0 | AA31: 5.8 | AB31: =AC31-Z31 -> 93.3 | AC31: 93.3 | AD31: 20 | AE31: =COUNTIF(I31:Y31,">10") -> 5 | AF31: 2 | AG31: 0 | AH31: 0 | AI31: 0 | AJ31: 0.29411765 | AK31: 0.125 | AL31: 0 | AM31: 0 | AN31: 0
A32: 2025 | B32: TE | C32: =IF(COUNTIF('Rookies 22-25'!$B$198:$B$349,E32)>0,"(R)","No") -> (R) | D32: 31 | E32: Gunnar Helm | F32: TEN | G32: =VLOOKUP(E32,'25 Draft ADP'!$B$3:$D$505,3,FALSE) -> 308 | H32: 16 | I32: 2.6 | J32: 2.9 | K32: 5.7 | L32: 2.2 | M32: 7.4 | N32: 3.5 | O32: 7.6 | P32: 10.3 | Q32: 2.5 | R32: BYE | S32: 6.9 | T32: 11.1 | U32: 8.3 | V32: 1.8 | W32: 14.9 | X32: 2.9 | Y32: 1.1 | Z32: 0 | AA32: 5.7 | AB32: =AC32-Z32 -> 91.7 | AC32: 91.7 | AD32: 20 | AE32: =COUNTIF(I32:Y32,">10") -> 3 | AF32: 0 | AG32: 0 | AH32: 0 | AI32: 0 | AJ32: 0.17647059 | AK32: 0 | AL32: 0 | AM32: 0 | AN32: 0
A33: 2025 | B33: TE | C33: =IF(COUNTIF('Rookies 22-25'!$B$198:$B$349,E33)>0,"(R)","No") -> (R) | D33: 32 | E33: Mason Taylor | F33: NYJ | G33: =VLOOKUP(E33,'25 Draft ADP'!$B$3:$D$505,3,FALSE) -> 178 | H33: 13 | I33: 3 | J33: 1.5 | K33: 5.8 | L33: 11.5 | M33: 17.7 | N33: 1.2 | O33: 6.1 | P33: 14.4 | Q33: BYE | R33: 1.4 | S33: 7 | T33: 5.1 | U33: 4.1 | V33: 10.1 | W33: - | X33: - | Y33: - | Z33: 0 | AA33: 6.8 | AB33: =AC33-Z33 -> 88.9 | AC33: 88.9 | AD33: 16 | AE33: =COUNTIF(I33:Y33,">10") -> 4 | AF33: 1 | AG33: 0 | AH33: 0 | AI33: 0 | AJ33: 0.23529412 | AK33: 0.076923077 | AL33: 0 | AM33: 0 | AN33: 0
A34: 2025 | B34: TE | C34: =IF(COUNTIF('Rookies 22-25'!$B$198:$B$349,E34)>0,"(R)","No") -> No | D34: 33 | E34: Darren Waller | F34: MIA | G34: =VLOOKUP(E34,'25 Draft ADP'!$B$3:$D$505,3,FALSE) -> 220 | H34: 9 | I34: - | J34: - | K34: - | L34: 17.7 | M34: 18.8 | N34: 9.2 | O34: 0 | P34: - | Q34: - | R34: - | S34: - | T34: BYE | U34: 6.7 | V34: 2.7 | W34: 25.6 | X34: 7 | Y34: 1 | Z34: 0 | AA34: 9.9 | AB34: =AC34-Z34 -> 88.7 | AC34: 88.7 | AD34: 17 | AE34: =COUNTIF(I34:Y34,">10") -> 3 | AF34: 3 | AG34: 1 | AH34: 1 | AI34: 0 | AJ34: 0.17647059 | AK34: 0.33333333 | AL34: 0.11111111 | AM34: 0.11111111 | AN34: 0
A35: 2025 | B35: TE | C35: =IF(COUNTIF('Rookies 22-25'!$B$198:$B$349,E35)>0,"(R)","No") -> No | D35: 34 | E35: David Njoku | F35: CLE | G35: =VLOOKUP(E35,'25 Draft ADP'!$B$3:$D$505,3,FALSE) -> 106 | H35: 12 | I35: 6.7 | J35: 8 | K35: 9 | L35: 3.1 | M35: 18.7 | N35: 5.8 | O35: - | P35: 13.7 | Q35: BYE | R35: 10.1 | S35: 1.7 | T35: 0 | U35: 2.4 | V35: 7.1 | W35: - | X35: - | Y35: - | Z35: 0 | AA35: 7.2 | AB35: =AC35-Z35 -> 86.3 | AC35: 86.3 | AD35: 9 | AE35: =COUNTIF(I35:Y35,">10") -> 3 | AF35: 1 | AG35: 0 | AH35: 0 | AI35: 0 | AJ35: 0.17647059 | AK35: 0.083333333 | AL35: 0 | AM35: 0 | AN35: 0
A36: 2025 | B36: TE | C36: =IF(COUNTIF('Rookies 22-25'!$B$198:$B$349,E36)>0,"(R)","No") -> No | D36: 35 | E36: Jonnu Smith | F36: PIT | G36: =VLOOKUP(E36,'25 Draft ADP'!$B$3:$D$505,3,FALSE) -> 169 | H36: 17 | I36: 12.5 | J36: 6.7 | K36: 5.3 | L36: 2.6 | M36: BYE | N36: 5.8 | O36: 11.8 | P36: 3.7 | Q36: 5.5 | R36: 1.4 | S36: 0 | T36: 5.8 | U36: 1.6 | V36: 0 | W36: 10.6 | X36: 2.8 | Y36: 7.7 | Z36: 1.4 | AA36: 5 | AB36: =AC36-Z36 -> 83.8 | AC36: 85.2 | AD36: 15 | AE36: =COUNTIF(I36:Y36,">10") -> 3 | AF36: 0 | AG36: 0 | AH36: 0 | AI36: 0 | AJ36: 0.17647059 | AK36: 0 | AL36: 0 | AM36: 0 | AN36: 0
A37: 2025 | B37: TE | C37: =IF(COUNTIF('Rookies 22-25'!$B$198:$B$349,E37)>0,"(R)","No") -> No | D37: 36 | E37: Cole Kmet | F37: CHI | G37: =VLOOKUP(E37,'25 Draft ADP'!$B$3:$D$505,3,FALSE) -> 257 | H37: 16 | I37: 4.1 | J37: 4.9 | K37: 8 | L37: 7.6 | M37: BYE | N37: 1 | O37: 2.6 | P37: - | Q37: 2 | R37: 1.5 | S37: 9.5 | T37: 1.3 | U37: 12.6 | V37: 6.2 | W37: 4.8 | X37: 3.4 | Y37: 3.6 | Z37: 5.6 | AA37: 4.9 | AB37: =AC37-Z37 -> 73.1 | AC37: 78.7 | AD37: 20 | AE37: =COUNTIF(I37:Y37,">10") -> 1 | AF37: 0 | AG37: 0 | AH37: 0 | AI37: 0 | AJ37: 0.058823529 | AK37: 0 | AL37: 0 | AM37: 0 | AN37: 0
A38: 2025 | B38: TE | C38: =IF(COUNTIF('Rookies 22-25'!$B$198:$B$349,E38)>0,"(R)","No") -> No | D38: 37 | E38: Noah Fant | F38: CIN | G38: =VLOOKUP(E38,'25 Draft ADP'!$B$3:$D$505,3,FALSE) -> 292 | H38: 15 | I38: 12.6 | J38: 5.8 | K38: 5.6 | L38: - | M38: 0 | N38: 6.7 | O38: 14.4 | P38: 7.1 | Q38: 10.8 | R38: BYE | S38: 6.6 | T38: 1.9 | U38: 1.3 | V38: 2.5 | W38: 0 | X38: - | Y38: 0 | Z38: -0.5 | AA38: 5 | AB38: =AC38-Z38 -> 75.3 | AC38: 74.8 | AD38: 20 | AE38: =COUNTIF(I38:Y38,">10") -> 3 | AF38: 0 | AG38: 0 | AH38: 0 | AI38: 0 | AJ38: 0.17647059 | AK38: 0 | AL38: 0 | AM38: 0 | AN38: 0
A39: 2025 | B39: TE | C39: =IF(COUNTIF('Rookies 22-25'!$B$198:$B$349,E39)>0,"(R)","No") -> No | D39: 38 | E39: Michael Mayer | F39: LV | G39: =VLOOKUP(E39,'25 Draft ADP'!$B$3:$D$505,3,FALSE) -> 280 | H39: 13 | I39: 7.8 | J39: 2.9 | K39: 0 | L39: - | M39: - | N39: 16 | O39: 2 | P39: BYE | Q39: 5.6 | R39: 5.2 | S39: 4.3 | T39: 2.4 | U39: - | V39: - | W39: 0 | X39: 2 | Y39: 17.9 | Z39: 7.7 | AA39: 5.7 | AB39: =AC39-Z39 -> 66.1 | AC39: 73.8 | AD39: 20 | AE39: =COUNTIF(I39:Y39,">10") -> 2 | AF39: 2 | AG39: 0 | AH39: 0 | AI39: 0 | AJ39: 0.11764706 | AK39: 0.15384615 | AL39: 0 | AM39: 0 | AN39: 0
A40: 2025 | B40: TE | C40: =IF(COUNTIF('Rookies 22-25'!$B$198:$B$349,E40)>0,"(R)","No") -> No | D40: 39 | E40: Darnell Washington | F40: PIT | G40: =VLOOKUP(E40,'25 Draft ADP'!$B$3:$D$505,3,FALSE) -> 369 | H40: 16 | I40: 0 | J40: 2 | K40: 0 | L40: 5 | M40: BYE | N40: 9.2 | O40: 9.2 | P40: 0 | Q40: 8.3 | R40: 2.5 | S40: 10.7 | T40: 4.2 | U40: 6.5 | V40: 2.2 | W40: 5.5 | X40: 4.6 | Y40: 3.5 | Z40: 0 | AA40: 4.6 | AB40: =AC40-Z40 -> 73.4 | AC40: 73.4 | AD40: 20 | AE40: =COUNTIF(I40:Y40,">10") -> 1 | AF40: 0 | AG40: 0 | AH40: 0 | AI40: 0 | AJ40: 0.058823529 | AK40: 0 | AL40: 0 | AM40: 0 | AN40: 0
...

Sheet Finish Points
A2: POS | B2: Top 2 | C2: *3-5 | D2: *6-10 | E2: *11-15 | F2: 16-25 | G2: 26-35 | H2: 36-50 | I2: 51-65 | J2: 66-80
A3: QB | B3: 22.896078 | C3: 20.79 | D3: 18.613333 | E3: 17.273333 | F3: 15.256667 | G3: 13.49 | H3: 11.5 | I3: n/a | J3: n/a
A4: RB | B4: 21.44 | C4: 18.61 | D4: 16.606667 | E4: 15.213333 | F4: 13.063333 | G4: 11.12 | H4: 7.72 | I4: 5.4 | J4: 4.16
A5: WR | B5: 21.91 | C5: 17.83 | D5: 16.2 | E5: 15.14 | F5: 13.8 | G5: 12.58 | H5: 10.38 | I5: 8.79 | J5: 6.67
A6: TE | B6: 14.79 | C6: 12.2 | D6: 10.8 | E6: 10.33 | F6: 7.8 | G6: 6.91 | H6: 4.41 | I6: n/a | J6: n/a

Sheet Rookies 22-25
A1: Rank | B1: Player (Bye) | C1: POS | D1: AVG | E1: Year
A2: 1 | B2: Bijan Robinson | C2: RB1 | D2: 1 | E2: 2023 | F2: {=_xlfn.LET(_xlpm.x,TRIM(B2),_xlpm.base,IFERROR(_xlfn.TEXTBEFORE(_xlpm.x," ("),_xlpm.x),_xlpm.teams,{"ARI","ATL","BAL","BUF","CAR","CHI","CIN","CLE","DAL","DEN","DET","GB","HOU","IND","JAX","KC","LV","LAC","LAR","MIA","MIN","NE","NO","NYG","NYJ","PHI","PIT","SEA","SF","TB","TEN","WAS"},_xlpm.team,_xlfn.XLOOKUP(TRUE,RIGHT(_xlpm.base,LEN(_xlpm.teams))=_xlpm.teams,_xlpm.teams,""),TRIM(LEFT(_xlpm.base,LEN(_xlpm.base)-LEN(_xlpm.team))))} -> Bijan Robinson
A3: 2 | B3: Jahmyr Gibbs | C3: RB2 | D3: 2 | E3: 2023 | F3: {=_xlfn.LET(_xlpm.x,TRIM(B3),_xlpm.base,IFERROR(_xlfn.TEXTBEFORE(_xlpm.x," ("),_xlpm.x),_xlpm.teams,{"ARI","ATL","BAL","BUF","CAR","CHI","CIN","CLE","DAL","DEN","DET","GB","HOU","IND","JAX","KC","LV","LAC","LAR","MIA","MIN","NE","NO","NYG","NYJ","PHI","PIT","SEA","SF","TB","TEN","WAS"},_xlpm.team,_xlfn.XLOOKUP(TRUE,RIGHT(_xlpm.base,LEN(_xlpm.teams))=_xlpm.teams,_xlpm.teams,""),TRIM(LEFT(_xlpm.base,LEN(_xlpm.base)-LEN(_xlpm.team))))} -> Jahmyr Gibbs
A4: 3 | B4: Jaxon Smith-Njigba | C4: WR1 | D4: 3 | E4: 2023 | F4: {=_xlfn.LET(_xlpm.x,TRIM(B4),_xlpm.base,IFERROR(_xlfn.TEXTBEFORE(_xlpm.x," ("),_xlpm.x),_xlpm.teams,{"ARI","ATL","BAL","BUF","CAR","CHI","CIN","CLE","DAL","DEN","DET","GB","HOU","IND","JAX","KC","LV","LAC","LAR","MIA","MIN","NE","NO","NYG","NYJ","PHI","PIT","SEA","SF","TB","TEN","WAS"},_xlpm.team,_xlfn.XLOOKUP(TRUE,RIGHT(_xlpm.base,LEN(_xlpm.teams))=_xlpm.teams,_xlpm.teams,""),TRIM(LEFT(_xlpm.base,LEN(_xlpm.base)-LEN(_xlpm.team))))} -> Jaxon Smith-Njigba
A5: 4 | B5: Jordan Addison | C5: WR2 | D5: 4.5 | E5: 2023 | F5: {=_xlfn.LET(_xlpm.x,TRIM(B5),_xlpm.base,IFERROR(_xlfn.TEXTBEFORE(_xlpm.x," ("),_xlpm.x),_xlpm.teams,{"ARI","ATL","BAL","BUF","CAR","CHI","CIN","CLE","DAL","DEN","DET","GB","HOU","IND","JAX","KC","LV","LAC","LAR","MIA","MIN","NE","NO","NYG","NYJ","PHI","PIT","SEA","SF","TB","TEN","WAS"},_xlpm.team,_xlfn.XLOOKUP(TRUE,RIGHT(_xlpm.base,LEN(_xlpm.teams))=_xlpm.teams,_xlpm.teams,""),TRIM(LEFT(_xlpm.base,LEN(_xlpm.base)-LEN(_xlpm.team))))} -> Jordan Addison
A6: 5 | B6: Anthony Richardson Sr. | C6: QB1 | D6: 6 | E6: 2023 | F6: {=_xlfn.LET(_xlpm.x,TRIM(B6),_xlpm.base,IFERROR(_xlfn.TEXTBEFORE(_xlpm.x," ("),_xlpm.x),_xlpm.teams,{"ARI","ATL","BAL","BUF","CAR","CHI","CIN","CLE","DAL","DEN","DET","GB","HOU","IND","JAX","KC","LV","LAC","LAR","MIA","MIN","NE","NO","NYG","NYJ","PHI","PIT","SEA","SF","TB","TEN","WAS"},_xlpm.team,_xlfn.XLOOKUP(TRUE,RIGHT(_xlpm.base,LEN(_xlpm.teams))=_xlpm.teams,_xlpm.teams,""),TRIM(LEFT(_xlpm.base,LEN(_xlpm.base)-LEN(_xlpm.team))))} -> Anthony Richardson Sr.
A7: 6 | B7: Quentin Johnston | C7: WR3 | D7: 6 | E7: 2023 | F7: {=_xlfn.LET(_xlpm.x,TRIM(B7),_xlpm.base,IFERROR(_xlfn.TEXTBEFORE(_xlpm.x," ("),_xlpm.x),_xlpm.teams,{"ARI","ATL","BAL","BUF","CAR","CHI","CIN","CLE","DAL","DEN","DET","GB","HOU","IND","JAX","KC","LV","LAC","LAR","MIA","MIN","NE","NO","NYG","NYJ","PHI","PIT","SEA","SF","TB","TEN","WAS"},_xlpm.team,_xlfn.XLOOKUP(TRUE,RIGHT(_xlpm.base,LEN(_xlpm.teams))=_xlpm.teams,_xlpm.teams,""),TRIM(LEFT(_xlpm.base,LEN(_xlpm.base)-LEN(_xlpm.team))))} -> Quentin Johnston
A8: 7 | B8: Zay Flowers | C8: WR4 | D8: 7.5 | E8: 2023 | F8: {=_xlfn.LET(_xlpm.x,TRIM(B8),_xlpm.base,IFERROR(_xlfn.TEXTBEFORE(_xlpm.x," ("),_xlpm.x),_xlpm.teams,{"ARI","ATL","BAL","BUF","CAR","CHI","CIN","CLE","DAL","DEN","DET","GB","HOU","IND","JAX","KC","LV","LAC","LAR","MIA","MIN","NE","NO","NYG","NYJ","PHI","PIT","SEA","SF","TB","TEN","WAS"},_xlpm.team,_xlfn.XLOOKUP(TRUE,RIGHT(_xlpm.base,LEN(_xlpm.teams))=_xlpm.teams,_xlpm.teams,""),TRIM(LEFT(_xlpm.base,LEN(_xlpm.base)-LEN(_xlpm.team))))} -> Zay Flowers
A9: 8 | B9: Dalton Kincaid | C9: TE1 | D9: 8.5 | E9: 2023 | F9: {=_xlfn.LET(_xlpm.x,TRIM(B9),_xlpm.base,IFERROR(_xlfn.TEXTBEFORE(_xlpm.x," ("),_xlpm.x),_xlpm.teams,{"ARI","ATL","BAL","BUF","CAR","CHI","CIN","CLE","DAL","DEN","DET","GB","HOU","IND","JAX","KC","LV","LAC","LAR","MIA","MIN","NE","NO","NYG","NYJ","PHI","PIT","SEA","SF","TB","TEN","WAS"},_xlpm.team,_xlfn.XLOOKUP(TRUE,RIGHT(_xlpm.base,LEN(_xlpm.teams))=_xlpm.teams,_xlpm.teams,""),TRIM(LEFT(_xlpm.base,LEN(_xlpm.base)-LEN(_xlpm.team))))} -> Dalton Kincaid
A10: 9 | B10: Zach Charbonnet | C10: RB3 | D10: 9 | E10: 2023 | F10: {=_xlfn.LET(_xlpm.x,TRIM(B10),_xlpm.base,IFERROR(_xlfn.TEXTBEFORE(_xlpm.x," ("),_xlpm.x),_xlpm.teams,{"ARI","ATL","BAL","BUF","CAR","CHI","CIN","CLE","DAL","DEN","DET","GB","HOU","IND","JAX","KC","LV","LAC","LAR","MIA","MIN","NE","NO","NYG","NYJ","PHI","PIT","SEA","SF","TB","TEN","WAS"},_xlpm.team,_xlfn.XLOOKUP(TRUE,RIGHT(_xlpm.base,LEN(_xlpm.teams))=_xlpm.teams,_xlpm.teams,""),TRIM(LEFT(_xlpm.base,LEN(_xlpm.base)-LEN(_xlpm.team))))} -> Zach Charbonnet
A11: 10 | B11: De'Von Achane | C11: RB4 | D11: 11 | E11: 2023 | F11: {=_xlfn.LET(_xlpm.x,TRIM(B11),_xlpm.base,IFERROR(_xlfn.TEXTBEFORE(_xlpm.x," ("),_xlpm.x),_xlpm.teams,{"ARI","ATL","BAL","BUF","CAR","CHI","CIN","CLE","DAL","DEN","DET","GB","HOU","IND","JAX","KC","LV","LAC","LAR","MIA","MIN","NE","NO","NYG","NYJ","PHI","PIT","SEA","SF","TB","TEN","WAS"},_xlpm.team,_xlfn.XLOOKUP(TRUE,RIGHT(_xlpm.base,LEN(_xlpm.teams))=_xlpm.teams,_xlpm.teams,""),TRIM(LEFT(_xlpm.base,LEN(_xlpm.base)-LEN(_xlpm.team))))} -> De'Von Acha
A12: 11 | B12: Bryce Young | C12: QB2 | D12: 12 | E12: 2023 | F12: {=_xlfn.LET(_xlpm.x,TRIM(B12),_xlpm.base,IFERROR(_xlfn.TEXTBEFORE(_xlpm.x," ("),_xlpm.x),_xlpm.teams,{"ARI","ATL","BAL","BUF","CAR","CHI","CIN","CLE","DAL","DEN","DET","GB","HOU","IND","JAX","KC","LV","LAC","LAR","MIA","MIN","NE","NO","NYG","NYJ","PHI","PIT","SEA","SF","TB","TEN","WAS"},_xlpm.team,_xlfn.XLOOKUP(TRUE,RIGHT(_xlpm.base,LEN(_xlpm.teams))=_xlpm.teams,_xlpm.teams,""),TRIM(LEFT(_xlpm.base,LEN(_xlpm.base)-LEN(_xlpm.team))))} -> Bryce Young
A13: 12 | B13: Kendre Miller | C13: RB5 | D13: 12 | E13: 2023 | F13: {=_xlfn.LET(_xlpm.x,TRIM(B13),_xlpm.base,IFERROR(_xlfn.TEXTBEFORE(_xlpm.x," ("),_xlpm.x),_xlpm.teams,{"ARI","ATL","BAL","BUF","CAR","CHI","CIN","CLE","DAL","DEN","DET","GB","HOU","IND","JAX","KC","LV","LAC","LAR","MIA","MIN","NE","NO","NYG","NYJ","PHI","PIT","SEA","SF","TB","TEN","WAS"},_xlpm.team,_xlfn.XLOOKUP(TRUE,RIGHT(_xlpm.base,LEN(_xlpm.teams))=_xlpm.teams,_xlpm.teams,""),TRIM(LEFT(_xlpm.base,LEN(_xlpm.base)-LEN(_xlpm.team))))} -> Kendre Miller
... A349: 152 | B349: Brant Kuithe | C349: TE27 | D349: 172 | E349: 2025 | F349: {=_xlfn.LET(_xlpm.x,TRIM(B349),_xlpm.base,IFERROR(_xlfn.TEXTBEFORE(_xlpm.x," ("),_xlpm.x),_xlpm.teams,{"ARI","ATL","BAL","BUF","CAR","CHI","CIN","CLE","DAL","DEN","DET","GB","HOU","IND","JAX","KC","LV","LAC","LAR","MIA","MIN","NE","NO","NYG","NYJ","PHI","PIT","SEA","SF","TB","TEN","WAS"},_xlpm.team,_xlfn.XLOOKUP(TRUE,RIGHT(_xlpm.base,LEN(_xlpm.teams))=_xlpm.teams,_xlpm.teams,""),TRIM(LEFT(_xlpm.base,LEN(_xlpm.base)-LEN(_xlpm.team))))} -> Brant Kuithe

Sheet 22 Draft ADP
A1: Rank | B1: Player (Bye) | C1: POS | D1: ADP | E1: POS | F1: Pos Finish
A2: 1 | B2: Jonathan Taylor | C2: RB1 | D2: 1 | E2: =LEFT(C2,2) -> RB | F2: =VALUE(MID(C2,3,LEN(C2))) -> 1
A3: 2 | B3: Christian McCaffrey | C3: RB2 | D3: 2 | E3: =LEFT(C3,2) -> RB | F3: =VALUE(MID(C3,3,LEN(C3))) -> 2
A4: 3 | B4: Justin Jefferson | C4: WR1 | D4: 3 | E4: =LEFT(C4,2) -> WR | F4: =VALUE(MID(C4,3,LEN(C4))) -> 1
A5: 4 | B5: Cooper Kupp | C5: WR2 | D5: 4 | E5: =LEFT(C5,2) -> WR | F5: =VALUE(MID(C5,3,LEN(C5))) -> 2
A6: 5 | B6: Austin Ekeler | C6: RB3 | D6: 5 | E6: =LEFT(C6,2) -> RB | F6: =VALUE(MID(C6,3,LEN(C6))) -> 3
A7: 6 | B7: Ja'Marr Chase | C7: WR3 | D7: 6 | E7: =LEFT(C7,2) -> WR | F7: =VALUE(MID(C7,3,LEN(C7))) -> 3
A8: 7 | B8: Dalvin Cook | C8: RB4 | D8: 7 | E8: =LEFT(C8,2) -> RB | F8: =VALUE(MID(C8,3,LEN(C8))) -> 4
A9: 8 | B9: Najee Harris | C9: RB5 | D9: 8 | E9: =LEFT(C9,2) -> RB | F9: =VALUE(MID(C9,3,LEN(C9))) -> 5
A10: 9 | B10: Derrick Henry | C10: RB6 | D10: 9 | E10: =LEFT(C10,2) -> RB | F10: =VALUE(MID(C10,3,LEN(C10))) -> 6
A11: 10 | B11: Stefon Diggs | C11: WR4 | D11: 10 | E11: =LEFT(C11,2) -> WR | F11: =VALUE(MID(C11,3,LEN(C11))) -> 4
A12: 11 | B12: Davante Adams | C12: WR5 | D12: 11 | E12: =LEFT(C12,2) -> WR | F12: =VALUE(MID(C12,3,LEN(C12))) -> 5
A13: 12 | B13: Joe Mixon | C13: RB7 | D13: 12 | E13: =LEFT(C13,2) -> RB | F13: =VALUE(MID(C13,3,LEN(C13))) -> 7
... A510: 510 | B510: Antoine Wesley | C510: WR200 | D510: 509 | E510: =LEFT(C510,2) -> WR | F510: =VALUE(MID(C510,3,LEN(C510))) -> 200

Sheet 23 Draft ADP
A1: Best Ball Average Draft Position (ADP) | Underdog and BB10s | Fantasy Football | FantasyPros
A2: Ending Rank | B2: Player (Bye) | C2: Finish POS | D2: Adp | E2: POS | F2: Pos Finish | I2: Average draft position according to fantasy pros
A3: 43 | B3: Justin Jefferson | C3: WR20 | D3: 1 | E3: =LEFT(C3,2) -> WR | F3: =VALUE(MID(C3,3,LEN(C3))) -> 20
A4: 1 | B4: Christian McCaffrey | C4: RB1 | D4: 2 | E4: =LEFT(C4,2) -> RB | F4: =VALUE(MID(C4,3,LEN(C4))) -> 1
A5: 44 | B5: Ja'Marr Chase | C5: WR21 | D5: 3 | E5: =LEFT(C5,2) -> WR | F5: =VALUE(MID(C5,3,LEN(C5))) -> 21
A6: 46 | B6: Austin Ekeler | C6: RB14 | D6: 4 | E6: =LEFT(C6,2) -> RB | F6: =VALUE(MID(C6,3,LEN(C6))) -> 14
A7: 2 | B7: Tyreek Hill | C7: WR1 | D7: 5 | E7: =LEFT(C7,2) -> WR | F7: =VALUE(MID(C7,3,LEN(C7))) -> 1
A8: 48 | B8: Bijan Robinson | C8: RB15 | D8: 6 | E8: =LEFT(C8,2) -> RB | F8: =VALUE(MID(C8,3,LEN(C8))) -> 15
A9: 3 | B9: Travis Kelce | C9: TE1 | D9: 7 | E9: =LEFT(C9,2) -> TE | F9: =VALUE(MID(C9,3,LEN(C9))) -> 1
A10: 4 | B10: CeeDee Lamb | C10: WR2 | D10: 8 | E10: =LEFT(C10,2) -> WR | F10: =VALUE(MID(C10,3,LEN(C10))) -> 2
A11: 5 | B11: Stefon Diggs | C11: WR3 | D11: 9 | E11: =LEFT(C11,2) -> WR | F11: =VALUE(MID(C11,3,LEN(C11))) -> 3
A12: 52 | B12: Saquon Barkley | C12: RB16 | D12: 10 | E12: =LEFT(C12,2) -> RB | F12: =VALUE(MID(C12,3,LEN(C12))) -> 16
A13: 53 | B13: Nick Chubb | C13: RB17 | D13: 11 | E13: =LEFT(C13,2) -> RB | F13: =VALUE(MID(C13,3,LEN(C13))) -> 17
A14: 6 | B14: A.J. Brown | C14: WR4 | D14: 12 | E14: =LEFT(C14,2) -> WR | F14: =VALUE(MID(C14,3,LEN(C14))) -> 4
... A322: 317 | B322: Jacoby Brissett | C322: QB44 | D322: 320 | E322: =LEFT(C322,2) -> QB | F322: =VALUE(MID(C322,3,LEN(C322))) -> 44
A323: 321 | B323: Gardner Minshew II | C323: QB46 | E323: =LEFT(C323,2) -> QB | F323: =VALUE(MID(C323,3,LEN(C323))) -> 46

Sheet 24 Draft ADP
A1: Best Ball Average Draft Position (ADP) | Underdog and BB10s | Fantasy Football | FantasyPros
A2: Rank | B2: Player (Bye) | C2: POS | D2: AVG | E2: POS | F2: POS Rank
A3: 1 | B3: Christian McCaffrey | C3: RB1 | D3: 1 | E3: =LEFT(C3,2) -> RB | F3: =VALUE(MID(C3,3,LEN(C3))) -> 1
A4: 2 | B4: CeeDee Lamb | C4: WR1 | D4: 2 | E4: =LEFT(C4,2) -> WR | F4: =VALUE(MID(C4,3,LEN(C4))) -> 1
A5: 3 | B5: Tyreek Hill | C5: WR2 | D5: 3 | E5: =LEFT(C5,2) -> WR | F5: =VALUE(MID(C5,3,LEN(C5))) -> 2
A6: 4 | B6: Breece Hall | C6: RB2 | D6: 4 | E6: =LEFT(C6,2) -> RB | F6: =VALUE(MID(C6,3,LEN(C6))) -> 2
A7: 5 | B7: Amon-Ra St. Brown | C7: WR3 | D7: 5 | E7: =LEFT(C7,2) -> WR | F7: =VALUE(MID(C7,3,LEN(C7))) -> 3
A8: 6 | B8: Bijan Robinson | C8: RB3 | D8: 6 | E8: =LEFT(C8,2) -> RB | F8: =VALUE(MID(C8,3,LEN(C8))) -> 3
A9: 7 | B9: Ja'Marr Chase | C9: WR4 | D9: 7 | E9: =LEFT(C9,2) -> WR | F9: =VALUE(MID(C9,3,LEN(C9))) -> 4
A10: 8 | B10: Justin Jefferson | C10: WR5 | D10: 8 | E10: =LEFT(C10,2) -> WR | F10: =VALUE(MID(C10,3,LEN(C10))) -> 5
A11: 9 | B11: A.J. Brown | C11: WR6 | D11: 9 | E11: =LEFT(C11,2) -> WR | F11: =VALUE(MID(C11,3,LEN(C11))) -> 6
A12: 10 | B12: Garrett Wilson | C12: WR7 | D12: 10 | E12: =LEFT(C12,2) -> WR | F12: =VALUE(MID(C12,3,LEN(C12))) -> 7
A13: 11 | B13: Jonathan Taylor | C13: RB4 | D13: 11 | E13: =LEFT(C13,2) -> RB | F13: =VALUE(MID(C13,3,LEN(C13))) -> 4
A14: 12 | B14: Puka Nacua | C14: WR8 | D14: 12 | E14: =LEFT(C14,2) -> WR | F14: =VALUE(MID(C14,3,LEN(C14))) -> 8
... A436: 465 | B436: DeWayne McBride | C436: RB119 | D436: 434 | E436: =LEFT(C436,2) -> RB | F436: =VALUE(MID(C436,3,LEN(C436))) -> 119

Sheet 25 Draft ADP
A1: Best Ball Average Draft Position (ADP) | Underdog and BB10s | Fantasy Football | FantasyPros
A2: Rank | B2: Player (Bye) | C2: POS | D2: ADP | E2: POS | F2: POS Rank
A3: 1 | B3: Ja'Marr Chase | C3: WR1 | D3: 1 | E3: =LEFT(C3,2) -> WR | F3: =VALUE(MID(C3,3,LEN(C3))) -> 1 | G3: {=_xlfn.LET(_xlpm.x,TRIM(B3),_xlpm.base,IFERROR(_xlfn.TEXTBEFORE(_xlpm.x," ("),_xlpm.x),_xlpm.teams,{"ARI","ATL","BAL","BUF","CAR","CHI","CIN","CLE","DAL","DEN","DET","GB","HOU","IND","JAX","KC","LV","LAC","LAR","MIA","MIN","NE","NO","NYG","NYJ","PHI","PIT","SEA","SF","TB","TEN","WAS"},_xlpm.team,_xlfn.XLOOKUP(TRUE,RIGHT(_xlpm.base,LEN(_xlpm.teams))=_xlpm.teams,_xlpm.teams,""),TRIM(LEFT(_xlpm.base,LEN(_xlpm.base)-LEN(_xlpm.team))))} -> Ja'Marr Chase
A4: 2 | B4: Bijan Robinson | C4: RB1 | D4: 2 | E4: =LEFT(C4,2) -> RB | F4: =VALUE(MID(C4,3,LEN(C4))) -> 1 | G4: {=_xlfn.LET(_xlpm.x,TRIM(B4),_xlpm.base,IFERROR(_xlfn.TEXTBEFORE(_xlpm.x," ("),_xlpm.x),_xlpm.teams,{"ARI","ATL","BAL","BUF","CAR","CHI","CIN","CLE","DAL","DEN","DET","GB","HOU","IND","JAX","KC","LV","LAC","LAR","MIA","MIN","NE","NO","NYG","NYJ","PHI","PIT","SEA","SF","TB","TEN","WAS"},_xlpm.team,_xlfn.XLOOKUP(TRUE,RIGHT(_xlpm.base,LEN(_xlpm.teams))=_xlpm.teams,_xlpm.teams,""),TRIM(LEFT(_xlpm.base,LEN(_xlpm.base)-LEN(_xlpm.team))))} -> Bijan Robinson
A5: 3 | B5: Jahmyr Gibbs | C5: RB2 | D5: 3 | E5: =LEFT(C5,2) -> RB | F5: =VALUE(MID(C5,3,LEN(C5))) -> 2 | G5: {=_xlfn.LET(_xlpm.x,TRIM(B5),_xlpm.base,IFERROR(_xlfn.TEXTBEFORE(_xlpm.x," ("),_xlpm.x),_xlpm.teams,{"ARI","ATL","BAL","BUF","CAR","CHI","CIN","CLE","DAL","DEN","DET","GB","HOU","IND","JAX","KC","LV","LAC","LAR","MIA","MIN","NE","NO","NYG","NYJ","PHI","PIT","SEA","SF","TB","TEN","WAS"},_xlpm.team,_xlfn.XLOOKUP(TRUE,RIGHT(_xlpm.base,LEN(_xlpm.teams))=_xlpm.teams,_xlpm.teams,""),TRIM(LEFT(_xlpm.base,LEN(_xlpm.base)-LEN(_xlpm.team))))} -> Jahmyr Gibbs
A6: 4 | B6: CeeDee Lamb | C6: WR2 | D6: 4 | E6: =LEFT(C6,2) -> WR | F6: =VALUE(MID(C6,3,LEN(C6))) -> 2 | G6: {=_xlfn.LET(_xlpm.x,TRIM(B6),_xlpm.base,IFERROR(_xlfn.TEXTBEFORE(_xlpm.x," ("),_xlpm.x),_xlpm.teams,{"ARI","ATL","BAL","BUF","CAR","CHI","CIN","CLE","DAL","DEN","DET","GB","HOU","IND","JAX","KC","LV","LAC","LAR","MIA","MIN","NE","NO","NYG","NYJ","PHI","PIT","SEA","SF","TB","TEN","WAS"},_xlpm.team,_xlfn.XLOOKUP(TRUE,RIGHT(_xlpm.base,LEN(_xlpm.teams))=_xlpm.teams,_xlpm.teams,""),TRIM(LEFT(_xlpm.base,LEN(_xlpm.base)-LEN(_xlpm.team))))} -> CeeDee Lamb
A7: 5 | B7: Saquon Barkley | C7: RB3 | D7: 5 | E7: =LEFT(C7,2) -> RB | F7: =VALUE(MID(C7,3,LEN(C7))) -> 3 | G7: {=_xlfn.LET(_xlpm.x,TRIM(B7),_xlpm.base,IFERROR(_xlfn.TEXTBEFORE(_xlpm.x," ("),_xlpm.x),_xlpm.teams,{"ARI","ATL","BAL","BUF","CAR","CHI","CIN","CLE","DAL","DEN","DET","GB","HOU","IND","JAX","KC","LV","LAC","LAR","MIA","MIN","NE","NO","NYG","NYJ","PHI","PIT","SEA","SF","TB","TEN","WAS"},_xlpm.team,_xlfn.XLOOKUP(TRUE,RIGHT(_xlpm.base,LEN(_xlpm.teams))=_xlpm.teams,_xlpm.teams,""),TRIM(LEFT(_xlpm.base,LEN(_xlpm.base)-LEN(_xlpm.team))))} -> Saquon Barkley
A8: 6 | B8: Justin Jefferson | C8: WR3 | D8: 6 | E8: =LEFT(C8,2) -> WR | F8: =VALUE(MID(C8,3,LEN(C8))) -> 3 | G8: {=_xlfn.LET(_xlpm.x,TRIM(B8),_xlpm.base,IFERROR(_xlfn.TEXTBEFORE(_xlpm.x," ("),_xlpm.x),_xlpm.teams,{"ARI","ATL","BAL","BUF","CAR","CHI","CIN","CLE","DAL","DEN","DET","GB","HOU","IND","JAX","KC","LV","LAC","LAR","MIA","MIN","NE","NO","NYG","NYJ","PHI","PIT","SEA","SF","TB","TEN","WAS"},_xlpm.team,_xlfn.XLOOKUP(TRUE,RIGHT(_xlpm.base,LEN(_xlpm.teams))=_xlpm.teams,_xlpm.teams,""),TRIM(LEFT(_xlpm.base,LEN(_xlpm.base)-LEN(_xlpm.team))))} -> Justin Jefferson
A9: 7 | B9: Christian McCaffrey | C9: RB4 | D9: 7 | E9: =LEFT(C9,2) -> RB | F9: =VALUE(MID(C9,3,LEN(C9))) -> 4 | G9: {=_xlfn.LET(_xlpm.x,TRIM(B9),_xlpm.base,IFERROR(_xlfn.TEXTBEFORE(_xlpm.x," ("),_xlpm.x),_xlpm.teams,{"ARI","ATL","BAL","BUF","CAR","CHI","CIN","CLE","DAL","DEN","DET","GB","HOU","IND","JAX","KC","LV","LAC","LAR","MIA","MIN","NE","NO","NYG","NYJ","PHI","PIT","SEA","SF","TB","TEN","WAS"},_xlpm.team,_xlfn.XLOOKUP(TRUE,RIGHT(_xlpm.base,LEN(_xlpm.teams))=_xlpm.teams,_xlpm.teams,""),TRIM(LEFT(_xlpm.base,LEN(_xlpm.base)-LEN(_xlpm.team))))} -> Christian McCaffrey
A10: 8 | B10: Nico Collins | C10: WR4 | D10: 8 | E10: =LEFT(C10,2) -> WR | F10: =VALUE(MID(C10,3,LEN(C10))) -> 4 | G10: {=_xlfn.LET(_xlpm.x,TRIM(B10),_xlpm.base,IFERROR(_xlfn.TEXTBEFORE(_xlpm.x," ("),_xlpm.x),_xlpm.teams,{"ARI","ATL","BAL","BUF","CAR","CHI","CIN","CLE","DAL","DEN","DET","GB","HOU","IND","JAX","KC","LV","LAC","LAR","MIA","MIN","NE","NO","NYG","NYJ","PHI","PIT","SEA","SF","TB","TEN","WAS"},_xlpm.team,_xlfn.XLOOKUP(TRUE,RIGHT(_xlpm.base,LEN(_xlpm.teams))=_xlpm.teams,_xlpm.teams,""),TRIM(LEFT(_xlpm.base,LEN(_xlpm.base)-LEN(_xlpm.team))))} -> Nico Collins
A11: 9 | B11: Amon-Ra St. Brown | C11: WR5 | D11: 9 | E11: =LEFT(C11,2) -> WR | F11: =VALUE(MID(C11,3,LEN(C11))) -> 5 | G11: {=_xlfn.LET(_xlpm.x,TRIM(B11),_xlpm.base,IFERROR(_xlfn.TEXTBEFORE(_xlpm.x," ("),_xlpm.x),_xlpm.teams,{"ARI","ATL","BAL","BUF","CAR","CHI","CIN","CLE","DAL","DEN","DET","GB","HOU","IND","JAX","KC","LV","LAC","LAR","MIA","MIN","NE","NO","NYG","NYJ","PHI","PIT","SEA","SF","TB","TEN","WAS"},_xlpm.team,_xlfn.XLOOKUP(TRUE,RIGHT(_xlpm.base,LEN(_xlpm.teams))=_xlpm.teams,_xlpm.teams,""),TRIM(LEFT(_xlpm.base,LEN(_xlpm.base)-LEN(_xlpm.team))))} -> Amon-Ra St. Brown
A12: 10 | B12: Malik Nabers | C12: WR6 | D12: 10 | E12: =LEFT(C12,2) -> WR | F12: =VALUE(MID(C12,3,LEN(C12))) -> 6 | G12: {=_xlfn.LET(_xlpm.x,TRIM(B12),_xlpm.base,IFERROR(_xlfn.TEXTBEFORE(_xlpm.x," ("),_xlpm.x),_xlpm.teams,{"ARI","ATL","BAL","BUF","CAR","CHI","CIN","CLE","DAL","DEN","DET","GB","HOU","IND","JAX","KC","LV","LAC","LAR","MIA","MIN","NE","NO","NYG","NYJ","PHI","PIT","SEA","SF","TB","TEN","WAS"},_xlpm.team,_xlfn.XLOOKUP(TRUE,RIGHT(_xlpm.base,LEN(_xlpm.teams))=_xlpm.teams,_xlpm.teams,""),TRIM(LEFT(_xlpm.base,LEN(_xlpm.base)-LEN(_xlpm.team))))} -> Malik Nabers
A13: 11 | B13: Ashton Jeanty | C13: RB5 | D13: 11 | E13: =LEFT(C13,2) -> RB | F13: =VALUE(MID(C13,3,LEN(C13))) -> 5 | G13: {=_xlfn.LET(_xlpm.x,TRIM(B13),_xlpm.base,IFERROR(_xlfn.TEXTBEFORE(_xlpm.x," ("),_xlpm.x),_xlpm.teams,{"ARI","ATL","BAL","BUF","CAR","CHI","CIN","CLE","DAL","DEN","DET","GB","HOU","IND","JAX","KC","LV","LAC","LAR","MIA","MIN","NE","NO","NYG","NYJ","PHI","PIT","SEA","SF","TB","TEN","WAS"},_xlpm.team,_xlfn.XLOOKUP(TRUE,RIGHT(_xlpm.base,LEN(_xlpm.teams))=_xlpm.teams,_xlpm.teams,""),TRIM(LEFT(_xlpm.base,LEN(_xlpm.base)-LEN(_xlpm.team))))} -> Ashton Jeanty
A14: 12 | B14: Derrick Henry | C14: RB6 | D14: 12 | E14: =LEFT(C14,2) -> RB | F14: =VALUE(MID(C14,3,LEN(C14))) -> 6 | G14: {=_xlfn.LET(_xlpm.x,TRIM(B14),_xlpm.base,IFERROR(_xlfn.TEXTBEFORE(_xlpm.x," ("),_xlpm.x),_xlpm.teams,{"ARI","ATL","BAL","BUF","CAR","CHI","CIN","CLE","DAL","DEN","DET","GB","HOU","IND","JAX","KC","LV","LAC","LAR","MIA","MIN","NE","NO","NYG","NYJ","PHI","PIT","SEA","SF","TB","TEN","WAS"},_xlpm.team,_xlfn.XLOOKUP(TRUE,RIGHT(_xlpm.base,LEN(_xlpm.teams))=_xlpm.teams,_xlpm.teams,""),TRIM(LEFT(_xlpm.base,LEN(_xlpm.base)-LEN(_xlpm.team))))} -> Derrick Henry
... A505: 535 | B505: Tyler Van Dyke | C505: QB80 | D505: 503 | E505: =LEFT(C505,2) -> QB | F505: =VALUE(MID(C505,3,LEN(C505))) -> 80 | G505: {=_xlfn.LET(_xlpm.x,TRIM(B505),_xlpm.base,IFERROR(_xlfn.TEXTBEFORE(_xlpm.x," ("),_xlpm.x),_xlpm.teams,{"ARI","ATL","BAL","BUF","CAR","CHI","CIN","CLE","DAL","DEN","DET","GB","HOU","IND","JAX","KC","LV","LAC","LAR","MIA","MIN","NE","NO","NYG","NYJ","PHI","PIT","SEA","SF","TB","TEN","WAS"},_xlpm.team,_xlfn.XLOOKUP(TRUE,RIGHT(_xlpm.base,LEN(_xlpm.teams))=_xlpm.teams,_xlpm.teams,""),TRIM(LEFT(_xlpm.base,LEN(_xlpm.base)-LEN(_xlpm.team))))} -> Tyler Van Dyke
